Workbook
Name __I______AU__E: #REF!
Name __I______AU__E: #REF!

Sheet Шаблон
A1: Банк номи | B1: АТ "Халқ банк"
A2: Вилоят номи | B2: Фаргона вилояти
A3: Филиал номи | B3: Бешариқ филиали
A4: МФО:
A5: Бошкарувчиси в.в.б. | B5: _____________
A6: Бошкарувчи уринбосари
A7: Кредит бўлими бошлиғи | B7: _____________
A8: Бош бухгалтер в.в.б. | B8: _____________
A9: Касса мудираси
A10: ВАШ назоратчиси
A11: ВАШ кассири
A12: ВАШ раками | B12: ________
A13: Аудит ходимлари: 1 | B13: А.Ҳазратқулов
A14: 2
A15: Текшириш санаси | B15: 2024 йил 1 январ
A16: Ўтган йилги ҳолат | B16: 2023 йил 1 январ
A18: Аудит ходими лавозими | B18: бўлим бошлиғи
A20: Изоҳ: | B20: Жадвалдаги листлар бўйича қуйидагича ўзгартиришлар киритилади:
A21: Кўк рангли лист | B21: Филиалнинг текшириш санасигача бўлган 1 йиллик айланма баланси қўйилади (ҳисоб рақамлар номи ҳамда жами кўрсатилган ҳолда)
A22: Оч қизил рангли лист | B22: Текшириш бошланган кундан якунланган кунгача бўлган айланма баланс қўйилади (ҳисоб рақамлар номи ҳамда жами қўрсатилган ҳолда)
A23: Тўқ яшил рангли лист | B23: Тегинилмайди, тайёр ҳисобот
A24: Оч яшил рангли лист | B24: 4 жадвалга фақат балансдан чиқарилган ва балансга киритилган асосий воситалар бўйича маълумотлар, 17 жадвалга смета ҳамда 23 жадвалга муддати ўтган ва муаммоли кредитлар бўйича маълумотлар киритилади. Қолгани тайёр
A25: Сариқ рангли лист | B25: Жадваллар тўлдирилиши лозим

Sheet Баланс
A1: IABS
A2: БХМ: 11350-КАРШИ Ш., АТ ХАЛК БАНКИ КАРШИ ШАХАР БХМ
A3: ТОШКЕНТ Ш., АТ ХАЛК БАНКИ ХИСОБ-КИТОБ МАРКАЗИ
A4: КОЛДИКЛАР ВА АЙЛАНМАЛАР ЖАМЛАНМА БАЛАНСИ ( 01.04.2023 - 31.03.2024)
A6: Ед.изм. сум/тийин
A7: 1 - Основные счета
A8: Х/р | B8: Хисоб ракам номи | C8: 01.04.2023га КИРИМ КОЛДИКЛАР | E8: АЙЛАНМАЛАР | G8: 10.11.2023га ЧИКИМ КОЛДИКЛАР
C9: АКТИВ | D9: ПАССИВ | E9: ДЕБЕТ | F9: КРЕДИТ | G9: АКТИВ | H9: ПАССИВ
A10: 1 АКТИВЛАР
A11: 10101 | B11: Айланма кассадаги накд пуллар | C11: 3.8367082e+09 | D11: 0 | E11: 7.0998354e+11 | F11: 6.9374752e+11 | G11: 1.641973e+10 | H11: 0
A12: 10103 | B12: Пул алмаштириш шахобчаларидаги накд пуллар | C12: 0 | D12: 0 | E12: 4.6553422e+09 | F12: 4.6553422e+09 | G12: 0 | H12: 0
A13: 10107 | B13: Банкоматлар ва бошка уз-узига хизмат курсатиш ускуналаридаги накд пуллар | C13: 4529309471 | D13: 0 | E13: 209775682599 | F13: 197034191932 | G13: 12749579164 | H13: 0
A14: 10109 | B14: Йулдаги накд пуллар ва бошка тулов хужжатлари | C14: 0 | D14: 0 | E14: 1.1055696e+12 | F14: 1.1057322e+12 | G14: 0 | H14: 0
A15: 10111 | B15: Амалиёт кассаларидаги накд пуллар | C15: 0 | D15: 0 | E15: 3.0978259e+11 | F15: 3.0978287e+11 | G15: 0 | H15: 0
A16: 10113 | B16: Пенсиялар, ижтимоий нафака, компенсациялар ва бошка туловларни бериш буйича махсус кассалардаги накд пуллар | C16: 0 | D16: 0 | E16: 1.4391042e+11 | F16: 1.4391042e+11 | G16: 0 | H16: 0
A17: 10198 | C17: 1000000 | D17: 0 | E17: 6.7939824e+08 | F17: 461908083 | G17: 221975545 | H17: 0
A18: Жами | B18: 10100 | C18: 8.3670177e+09 | D18: 0 | E18: 2.4843566e+12 | F18: 2.4553245e+12 | G18: 2.9391285e+10 | H18: 0
A19: 10307 | B19: Марказий банкдан олиниши лозим булган маблаглар - Накд пуллар | C19: 0 | D19: 0 | E19: 119500000000 | F19: 119500000000 | G19: 0 | H19: 0
A20: 10311 | B20: Марказий банкдан олишини лозим булган маблаглар - топширилган накд пуллар | C20: 0 | D20: 0 | E20: 3161000000 | F20: 3161000000 | G20: 0 | H20: 0
A21: Жами | B21: 10300 | C21: 0 | D21: 0 | E21: 122661000000 | F21: 122661000000 | G21: 0 | H21: 0
A22: 10507 | B22: Бошка банклардан вакиллик хисобваракларидан олиниши лозим булган маблаглар - Накд пуллар | C22: 0 | D22: 0 | E22: 69500000000 | F22: 69500000000 | G22: 0 | H22: 0
A23: 10511 | B23: Жисм. шахс. банк карталаридан берилган накд пул м-глари б-ча бошка банклардан олиниши лозим булган м-глар | C23: 1.1008382e+08 | D23: 0 | E23: 1.7862228e+09 | F23: 1775850250 | G23: 10372539 | H23: 0
A24: 10513 | B24: Банк карталаридан амалга оширилган туловлар буйича бошка банклардан олиниши лозим булган маблаглар | C24: 1.1936612e+09 | D24: 0 | E24: 1.580008e+10 | F24: 1.4574706e+10 | G24: 1.2253741e+09 | H24: 0
A25: Жами | B25: 10500 | C25: 1.303745e+09 | D25: 0 | E25: 8.7086302e+10 | F25: 8.5850556e+10 | G25: 1.2357466e+09 | H25: 0
A26: 12503 | B26: Жисмоний шахсларга банк карталари оркали берилган киска муддатли кредитлар | C26: 15717856 | D26: 0 | E26: 6.7143841e+08 | F26: 5.3055412e+08 | G26: 1.4088429e+08 | H26: 0
A27: 12505 | B27: Жисмоний шахсларга берилган муддати утган кредитлар | C27: 2.6453235e+09 | D27: 0 | E27: 1.1983807e+10 | F27: 9.3957007e+09 | G27: 2.5881068e+09 | H27: 0
A28: 12521 | B28: Жисмоний шахсларга махсус дастурлар буйича берилган киска муддатли кредитлар | C28: 8.8098929e+08 | D28: 0 | E28: 1.2814971e+09 | F28: 8.4726169e+08 | G28: 4.3423545e+08 | H28: 0
A29: 12531 | C29: 0 | D29: 0 | E29: 5000000 | F29: 420426.5 | G29: 4579573.5 | H29: 0
A30: 12541 | C30: 0 | D30: 0 | E30: 75000000 | F30: 3279930.8 | G30: 71720069 | H30: 0
A31: 12599 | B31: Курилиши мумкин булган зарарларни копл.зах. - Жисм.шахсларга берилган киска муддатли кредитлар (контр-актив) | C31: 0 | D31: 93819686 | E31: 2.0004832e+08 | F31: 2.6791589e+08 | G31: 0 | H31: 67867569
A32: Жами | B32: 12500 | C32: 3.5420306e+09 | D32: 93819686 | E32: 1.4216791e+10 | F32: 1.1045133e+10 | G32: 3.2395262e+09 | H32: 67867569
A33: 12605 | B33: Якка тартибдаги тадбиркорларга берилган муддати утган кредитлар | C33: 68594471 | D33: 0 | E33: 2.9736457e+08 | F33: 2.4879001e+08 | G33: 48574556 | H33: 0
A34: Жами | B34: 12600 | C34: 68594471 | D34: 0 | E34: 2.9736457e+08 | F34: 2.4879001e+08 | G34: 48574556 | H34: 0
A35: 13105 | B35: Хусусий корхоналар, хужалик ширкатлари ва жамиятларга берилган муддати утган кредитлар | C35: 4.2927403e+08 | D35: 0 | E35: 1.8291472e+10 | F35: 7.3285236e+09 | G35: 1.10724e+10 | H35: 0
A36: 13199 | B36: Кур-и мумкин булган зарар. копл. зах.- Хусусий корх, хуж.ширкатлари ва жамиятларга б-ган киска муд.кр. (к-акт) | C36: 0 | D36: 225000000 | E36: 6.0301866e+08 | F36: 850549764 | G36: 0 | H36: 2.475311e+08
A37: Жами | B37: 13100 | C37: 4.2927403e+08 | D37: 225000000 | E37: 1.889449e+10 | F37: 8.1790733e+09 | G37: 1.10724e+10 | H37: 2.475311e+08
A38: 14301 | B38: Давлат эхтиёжлари учун харид килинадиган пахта хом-ашёсини етиштириш учун берилган узок муддатли кредитлар | C38: 0 | D38: 0 | E38: 50644128 | F38: 0 | G38: 50644128 | H38: 0
A39: Жами | B39: 14300 | C39: 0 | D39: 0 | E39: 50644128 | F39: 0 | G39: 50644128 | H39: 0
A40: 14901 | B40: Жисмоний шахсларга берилган узок муддатли кредитлар | C40: 4.6146272e+10 | D40: 0 | E40: 6.4506013e+10 | F40: 3.652958e+09 | G40: 6.0853055e+10 | H40: 0
A41: 14903 | B41: Жисмоний шахсларга давлат дастурлари буйича уй-жой сотиб олиш учун берилган узок муддатли ипотека кредитлари | C41: 3.7565358e+10 | D41: 0 | E41: 5.9345582e+10 | F41: 3.0418913e+09 | G41: 5.6303691e+10 | H41: 0
...

Sheet 1.активлар
G1: 1-жадвал
A2: =""&(Шаблон!B1)&"нинг "&(Шаблон!B2)&" "&(Шаблон!B3)&" бўйича "&(Шаблон!B15)&" ҳолатига активлар ТАҲЛИЛИ" -> АТ "Халқ банк"нинг Фаргона вилояти Бешариқ филиали бўйича 2024 йил 1 январ ҳолатига активлар ТАҲЛИЛИ
G3: (минг сўмда)
A4: Т/р | B4: Активлар таркиби | C4: =""&(Шаблон!B16)&" ҳолатига" -> 2023 йил 1 январ ҳолатига | E4: =""&(Шаблон!B15)&" ҳолатига" -> 2024 йил 1 январ ҳолатига | G4: фарқи (+;-)
C5: Сумма | D5: фоиз | E5: Сумма | F5: фоиз
A6: I. | B6: Даромад келтирувчи активлар | C6: =C7+C8+C10+C9+C12+C13+C14+C11 -> 3.1172742e+08 | D6: =+(C6+C32)*100/C30 -> 6.0557821 | E6: =E7+E8+E10+E9+E12+E13+E14+E11 -> 3.891274e+08 | F6: =+E6*100/E30 -> 82.242727 | G6: =G7+G8+G10+G9+G12+G13+G14+G11 -> 77399975 | H6: =+(E6+E32)-(C6+C32) -> -24680320
A7: а | B7: - факторинг | C7: =SUM(SUMIF(Баланс!$B:$B,11100,Баланс!$C:$C)/1000,0) -> 0 | D7: =C7/C6*100 -> 0 | E7: =SUM(SUMIF(Баланс!$B:$B,11100,Баланс!$G:$G)/1000,0) -> 0 | F7: =E7/E6*100 -> 0 | G7: =SUM(E7-C7) -> 0
A8: б | B8: - қисқа муддатли ва муддати утган ссудалар | C8: =SUM(SUMIF(Баланс!$B:$B,12600,Баланс!$C:$C)/1000+SUMIF(Баланс!$B:$B,12100,Баланс!$C:$C)/1000+SUMIF(Баланс!$B:$B,12300,Баланс!$C:$C)/1000+SUMIF(Баланс!$B:$B,12400,Баланс!$C:$C)/1000+SUMIF(Баланс!$B:$B,12500,Баланс!$C:$C)/1000+SUMIF(Баланс!$B:$B,12700,Баланс!$C:$C)/1000+SUMIF(Баланс!$B:$B,12900,Баланс!$C:$C)/1000+SUMIF(Баланс!$B:$B,13000,Баланс!$C:$C)/1000+SUMIF(Баланс!$B:$B,13100,Баланс!$C:$C)/1000+SUMIF(Баланс!$B:$B,13200,Баланс!$C:$C)/1000+SUMIF(Баланс!$B:$B,13300,Баланс!$C:$C)/1000,0) -> 4039899.2 | D8: =C8/C6*100 -> 1.2959717 | E8: =SUM(SUMIF(Баланс!$B:$B,12600,Баланс!$G:$G)/1000+SUMIF(Баланс!$B:$B,12100,Баланс!$G:$G)/1000+SUMIF(Баланс!$B:$B,12300,Баланс!$G:$G)/1000+SUMIF(Баланс!$B:$B,12400,Баланс!$G:$G)/1000+SUMIF(Баланс!$B:$B,12500,Баланс!$G:$G)/1000+SUMIF(Баланс!$B:$B,12700,Баланс!$G:$G)/1000+SUMIF(Баланс!$B:$B,12900,Баланс!$G:$G)/1000+SUMIF(Баланс!$B:$B,13000,Баланс!$G:$G)/1000+SUMIF(Баланс!$B:$B,13100,Баланс!$G:$G)/1000+SUMIF(Баланс!$B:$B,13200,Баланс!$G:$G)/1000+SUMIF(Баланс!$B:$B,13300,Баланс!$G:$G)/1000,0) -> 14360501 | F8: =E8/E6*100 -> 3.6904368 | G8: =SUM(E8-C8) -> 10320602
A9: в | B9: - узоқ муддатли ссудалар | C9: =SUM(SUMIF(Баланс!$B:$B,14300,Баланс!$C:$C)/1000+SUMIF(Баланс!$B:$B,14500,Баланс!$C:$C)/1000+SUMIF(Баланс!$B:$B,14700,Баланс!$C:$C)/1000+SUMIF(Баланс!$B:$B,14900,Баланс!$C:$C)/1000+SUMIF(Баланс!$B:$B,15000,Баланс!$C:$C)/1000+SUMIF(Баланс!$B:$B,15100,Баланс!$C:$C)/1000+SUMIF(Баланс!$B:$B,15200,Баланс!$C:$C)/1000+SUMIF(Баланс!$B:$B,15300,Баланс!$C:$C)/1000+SUMIF(Баланс!$B:$B,15400,Баланс!$C:$C)/1000+SUMIF(Баланс!$B:$B,15500,Баланс!$C:$C)/1000,0)+SUMIF(Баланс!$B:$B,14800,Баланс!$C:$C)/1000 -> 1.9159241e+08 | D9: =(C9+C32)/C6*100 -> -31.460595 | E9: =SUM(SUMIF(Баланс!$B:$B,14300,Баланс!$G:$G)/1000+SUMIF(Баланс!$B:$B,14500,Баланс!$G:$G)/1000+SUMIF(Баланс!$B:$B,14700,Баланс!$G:$G)/1000+SUMIF(Баланс!$B:$B,14900,Баланс!$G:$G)/1000+SUMIF(Баланс!$B:$B,15000,Баланс!$G:$G)/1000+SUMIF(Баланс!$B:$B,15100,Баланс!$G:$G)/1000+SUMIF(Баланс!$B:$B,15200,Баланс!$G:$G)/1000+SUMIF(Баланс!$B:$B,15300,Баланс!$G:$G)/1000+SUMIF(Баланс!$B:$B,15400,Баланс!$G:$G)/1000+SUMIF(Баланс!$B:$B,15500,Баланс!$G:$G)/1000,0)+SUMIF(Баланс!$B:$B,14800,Баланс!$G:$G)/1000 -> 2.4454243e+08 | F9: =(E9)/E6*100 -> 62.843797 | G9: =SUM(E9-C9) -> 52950024 | H9: =+(E9+E32)-(C9+C32) -> -49130271
A10: г | B10: - лизинг | C10: 0 | D10: =C10/C6*100 -> 0 | E10: 0 | F10: =E10/E6*100 -> 0 | G10: =SUM(E10-C10) -> 0
A11: д | B11: -Суд жараёнидаги кредитлар ва лизинг | C11: =SUM(SUMIF(Баланс!$B:$B,15700,Баланс!$C:$C)/1000) -> 59138.512 | D11: =+C11/C6*100 -> 0.018971225 | E11: =SUM(SUMIF(Баланс!$B:$B,15700,Баланс!$G:$G)/1000) -> 32804.978 | F11: =+E11/E6*100 -> 0.0084303953 | G11: =SUM(E11-C11) -> -26333.534
A12: е | B12: - сўндириш муддатигача сакланадиган карз кимматли когозларга килинган инвестициялар | C12: =SUM(SUMIF(Баланс!$B:$B,15900,Баланс!$C:$C)/1000,0) -> 0 | D12: =C12/C6*100 -> 0 | E12: =SUM(SUMIF(Баланс!$B:$B,15900,Баланс!$G:$G)/1000,0) -> 0 | F12: =E12/E6*100 -> 0 | G12: =SUM(E12-C12) -> 0
A13: ж | B13: - қўшма корхоналарга инвестиция | C13: =SUM(SUMIF(Баланс!$B:$B,15800,Баланс!$C:$C)/1000,0) -> 0 | D13: =C13/C6*100 -> 0 | E13: =SUM(SUMIF(Баланс!$B:$B,15800,Баланс!$G:$G)/1000,0) -> 0 | F13: =E13/E6*100 -> 0 | G13: =SUM(E13-C13) -> 0
A14: ё | B14: - банк филиалларига берилган молиявий ёрдам ва ресурслар | C14: =SUM(SUMIF(Баланс!$A:$A,16101,Баланс!$C:$C)/1000+SUMIF(Баланс!$A:$A,16102,Баланс!$C:$C)/1000,0) -> 1.1603598e+08 | D14: =C14/C6*100 -> 37.223539 | E14: =SUM(SUMIF(Баланс!$A:$A,16101,Баланс!$G:$G)/1000+SUMIF(Баланс!$A:$A,16102,Баланс!$G:$G)/1000,0) -> 1.3019166e+08 | F14: =E14/E6*100 -> 33.457336 | G14: =SUM(E14-C14) -> 14155682 | H14: =+E8+E9 -> 2.5890293e+08
A15: II. | B15: Даромад келтирмайдиган активлар | C15: =SUM(C16:C23) -> 52613863 | D15: =C15/C30*100 -> 14.440818 | E15: =SUM(E16:E23) -> 84017657 | F15: =E15/E30*100 -> 17.757273 | G15: =SUM(E15-C15) -> 31403794 | H15: =+H14/E14*100 -> 198.86292
A16: а | B16: - бош офисдан товар материал олиш учун ўтказилган маблағлар | C16: =SUM(SUMIF(Баланс!$A:$A,16104,Баланс!$C:$C)/1000+SUMIF(Баланс!$A:$A,16105,Баланс!$C:$C)/1000+SUMIF(Баланс!$A:$A,16107,Баланс!$C:$C)/1000+SUMIF(Баланс!$A:$A,16109,Баланс!$C:$C)/1000,0) -> 0 | D16: =C16/C15*100 -> 0 | E16: =SUM(SUMIF(Баланс!$A:$A,16104,Баланс!$G:$G)/1000+SUMIF(Баланс!$A:$A,16105,Баланс!$G:$G)/1000+SUMIF(Баланс!$A:$A,16107,Баланс!$G:$G)/1000+SUMIF(Баланс!$A:$A,16109,Баланс!$G:$G)/1000,0) -> 0 | F16: =E16/E15*100 -> 0 | G16: =SUM(E16-C16) -> 0
A17: б | B17: - ҳисобланган, лекин ундирилмаган фоизлар | C17: =SUM(SUMIF(Баланс!$B:$B,16300,Баланс!$C:$C)/1000+SUMIF(Баланс!$B:$B,16400,Баланс!$C:$C)/1000,0) -> 12488981 | D17: =C17/C15*100 -> 23.737054 | E17: =SUM(SUMIF(Баланс!$B:$B,16300,Баланс!$G:$G)/1000+SUMIF(Баланс!$B:$B,16400,Баланс!$G:$G)/1000,0) -> 21636700 | F17: =E17/E15*100 -> 25.752563 | G17: =SUM(E17-C17) -> 9147718.7
A18: в | B18: - банк мулклари | C18: =SUM(SUMIF(Баланс!$B:$B,16500,Баланс!$C:$C)/1000+SUMIF(Баланс!$B:$B,16600,Баланс!$C:$C)/1000+SUMIF(Баланс!$B:$B,16700,Баланс!$C:$C)/1000,0) -> 12169966 | D18: =C18/C15*100 -> 23.130721 | E18: =SUM(SUMIF(Баланс!$B:$B,16500,Баланс!$G:$G)/1000+SUMIF(Баланс!$B:$B,16600,Баланс!$G:$G)/1000+SUMIF(Баланс!$B:$B,16700,Баланс!$G:$G)/1000,0) -> 21895680 | F18: =E18/E15*100 -> 26.060808 | G18: =SUM(E18-C18) -> 9725714.5
A19: г | B19: - чет эл валюталарининг сўмдаги қиймати | C19: =SUM(SUMIF(Баланс!$B:$B,17100,Баланс!$C:$C)/1000,0) -> 2172324 | D19: =C19/C15*100 -> 4.1288054 | E19: =SUM(SUMIF(Баланс!$B:$B,17100,Баланс!$G:$G)/1000,0) -> 4997355.4 | F19: =E19/E15*100 -> 5.9479823 | G19: =SUM(E19-C19) -> 2825031.4
A20: д | B20: - транзит счетлар | C20: =SUM(SUMIF(Баланс!$B:$B,17300,Баланс!$C:$C)/1000,0)+SUM(SUMIF(Баланс!$B:$B,17400,Баланс!$C:$C)/1000,0) -> 605010.44 | D20: =C20/C15*100 -> 1.1499069 | E20: =SUM(SUMIF(Баланс!$B:$B,17300,Баланс!$G:$G)/1000,0)+SUM(SUMIF(Баланс!$B:$B,17400,Баланс!$G:$G)/1000,0) -> 494345.42 | F20: =E20/E15*100 -> 0.58838278 | G20: =SUM(E20-C20) -> -110665.02
A21: е | B21: - давлат ҳисоб рақамлари | C21: =SUM(SUMIF(Баланс!$B:$B,17500,Баланс!$C:$C)/1000,0)+SUM(SUMIF(Баланс!$B:$B,10700,Баланс!$C:$C)/1000,0)+SUM(SUMIF(Баланс!$B:$B,10800,Баланс!$C:$C)/1000,0) -> 0 | D21: =C21/C15*100 -> 0 | E21: =SUM(SUMIF(Баланс!$B:$B,17500,Баланс!$G:$G)/1000,0)+SUM(SUMIF(Баланс!$B:$B,10700,Баланс!$G:$G)/1000,0)+SUM(SUMIF(Баланс!$B:$B,10800,Баланс!$G:$G)/1000,0) -> 0 | F21: =E21/E15*100 -> 0 | G21: =SUM(E21-C21) -> 0
A22: ё | B22: - бошқа активлар | C22: =SUM(SUMIF(Баланс!$B:$B,19900,Баланс!$C:$C)/1000,0) -> 952064.3 | D22: =C22/C15*100 -> 1.8095313 | E22: =SUM(SUMIF(Баланс!$B:$B,19900,Баланс!$G:$G)/1000,0) -> 1019650.3 | F22: =E22/E15*100 -> 1.2136143 | G22: =SUM(E22-C22) -> 67586
A23: ж | B23: - юқори ликвидли активлар | C23: =SUM(C25:C29) -> 24225517 | D23: =C23/C15*100 -> 46.043982 | E23: =SUM(E25:E29) -> 33973926 | F23: =E23/E15*100 -> 40.43665 | G23: =SUM(G25:G28) -> 6425757.7
B24: шундан :
B25: - кассадаги нақд пуллар ва қимматбаҳо металлар | C25: =SUM(SUMIF(Баланс!$B:$B,10100,Баланс!$C:$C)/1000,0)-SUMIF(Баланс!$A:$A,10109,Баланс!$C:$C)/1000 -> 8367017.7 | D25: =C25/C23*100 -> 34.538035 | E25: =SUM(SUMIF(Баланс!$B:$B,10100,Баланс!$G:$G)/1000,0)-SUMIF(Баланс!$A:$A,10109,Баланс!$G:$G)/1000 -> 29391285 | F25: =E25/E23*100 -> 86.5113 | G25: =SUM(E25-C25) -> 21024267
B26: - йўлдаги пуллар | C26: =SUM(SUMIF(Баланс!$B:$B,10300,Баланс!$C:$C)/1000+SUMIF(Баланс!$B:$B,10500,Баланс!$C:$C)/1000+SUMIF(Баланс!$A:$A,10109,Баланс!$C:$C)/1000-SUMIF(Баланс!$A:$A,10309,Баланс!$C:$C)/1000,0) -> 1303745 | D26: =C26/C23*100 -> 5.3817013 | E26: =SUM(SUMIF(Баланс!$B:$B,10300,Баланс!$G:$G)/1000+SUMIF(Баланс!$B:$B,10500,Баланс!$G:$G)/1000,0)+SUMIF(Баланс!$A:$A,10109,Баланс!$G:$G)/1000-SUMIF(Баланс!$A:$A,10309,Баланс!$G:$G)/1000 -> 1235746.6 | F26: =E26/E23*100 -> 3.6373383 | G26: =SUM(E26-C26) -> -67998.385
B27: - мажбурий заҳира фондидаги маблағлар | C27: =SUM(SUMIF(Баланс!$A:$A,10309,Баланс!$C:$C)/1000,0) -> 0 | D27: =C27/C23*100 -> 0 | E27: =SUM(SUMIF(Баланс!$A:$A,10309,Баланс!$G:$G)/1000,0) -> 0 | F27: =E27/E23*100 -> 0 | G27: =SUM(E27-C27) -> 0
B28: - ягона вакиллик ҳисобварағидаги маблағлар | C28: =SUM(SUMIF(Баланс!$A:$A,16103,Баланс!$C:$C)/1000,0) -> 14530511 | D28: =C28/C23*100 -> 59.980189 | E28: =SUM(SUMIF(Баланс!$A:$A,16103,Баланс!$G:$G)/1000,0) -> 0 | F28: =E28/E23*100 -> 0 | G28: =SUM(E28-C28) -> -14530511
B29: -паластик картлардан амалга оширилган туловлар буйича бошка банклардан олинадиган маблаглар | C29: =SUM(SUMIF(Баланс!$A:$A,16113,Баланс!$C:$C)/1000,0)+SUM(SUMIF(Баланс!$A:$A,16111,Баланс!$C:$C)/1000,0) -> 24243.549 | D29: =+C29/C23*100 -> 0.10007443 | E29: =SUM(SUMIF(Баланс!$A:$A,16113,Баланс!$G:$G)/1000,0)+SUM(SUMIF(Баланс!$A:$A,16111,Баланс!$G:$G)/1000,0) -> 3346894.3 | F29: =+E29/E23*100 -> 9.8513616
B30: Жами активлар | C30: =C15+C6 -> 3.6434128e+08 | D30: =D15+D6 -> 20.4966 | E30: =E15+E6 -> 4.7314505e+08 | F30: =F15+F6 -> 100 | G30: =SUM(E30-C30) -> 1.0880377e+08
C31: =74677576742.35/1000 -> 74677577 | E31: =81401050229.17/1000 -> 81401050
C32: =+C31-C30 -> -2.8966371e+08 | E32: =+E31-E30 -> -3.91744e+08
B34: =""&(Шаблон!B1)&"нинг Ички аудит" -> АТ "Халқ банк"нинг Ички аудит
B35: департаменти бўлим бошлиғи: | F35: =Шаблон!B13 -> А.Ҳазратқулов
B37: =""&(Шаблон!B1)&" "&(Шаблон!B2)&"" -> АТ "Халқ банк" Фаргона вилояти
B38: =""&(Шаблон!B3)&" бошқарувчиси:" -> Бешариқ филиали бошқарувчиси: | F38: =Шаблон!B5 -> _____________
B40: Бош бухгалтери: | F40: =Шаблон!B8 -> _____________

Sheet 4.а-восита
L1: 4-жадвал
A2: =""&(Шаблон!B1)&"нинг "&(Шаблон!B2)&" вилоят "&(Шаблон!B3)&" филиали бўйича "&(Шаблон!B15)&" ҳолатига асосий воситалар ТАҲЛИЛИ" -> АТ "Халқ банк"нинг Фаргона вилояти вилоят Бешариқ филиали филиали бўйича 2024 йил 1 январ ҳолатига асосий воситалар ТАҲЛИЛИ
L3: (минг сўмда)
A4: Т\р | B4: Асосий воситалар ҳаракати | C4: Тугалланмаган қурилишлар | D4: Бино ва иншоат | E4: Ижарага олинган а/в | F4: Транспорт | G4: Мебел ва қурилма | H4: Номоддий активлар | I4: Терминаллар ва тулов карталари | J4: Ижарадаги асосий воситалар | K4: Омбордаги асосий воситалар | L4: Жами
A5: I | B5: Асосий воситалар
A6: а) | B6: =""&(Шаблон!B16)&" ҳолатига қолдиқ" -> 2023 йил 1 январ ҳолатига қолдиқ | C6: =SUM(SUMIF(Баланс!$A:$A,16505,Баланс!$C:$C)/1000,0) -> 0 | D6: =SUM(SUMIF(Баланс!$A:$A,16509,Баланс!$C:$C)/1000,0) -> 4016869.6 | E6: =SUM(SUMIF(Баланс!$A:$A,16515,Баланс!$C:$C)/1000,0) -> 0 | F6: =SUM(SUMIF(Баланс!$A:$A,16529,Баланс!$C:$C)/1000,0) -> 810919.33 | G6: =SUM(SUMIF(Баланс!$A:$A,16535,Баланс!$C:$C)/1000,0) -> 2748798.5 | H6: =SUM(SUMIF(Баланс!$A:$A,16601,Баланс!$C:$C)/1000,0) -> 0 | I6: =SUM(SUMIF(Баланс!$A:$A,16541,Баланс!$C:$C)/1000,0) -> 3208281.2 | J6: =SUM(SUMIF(Баланс!$A:$A,16549,Баланс!$C:$C)/1000,0) -> 0 | K6: =SUM(SUMIF(Баланс!$A:$A,16561,Баланс!$C:$C)/1000,0) -> 64039.594 | L6: =SUM(C6:K6) -> 10848908
A7: б) | B7: ҳисобдан чиқиши | C7: =SUM(C8:C13) -> 0 | D7: =SUM(D8:D13) -> 0 | E7: =SUM(E8:E13) -> 0 | F7: =SUM(F8:F13) -> 4274.9 | G7: =SUM(G8:G13) -> 0 | H7: =SUM(H8:H13) -> 0 | I7: =SUM(I8:I13) -> 0 | J7: =SUM(J8:J13) -> 0 | ... L7: =SUM(L8:L13) -> 103658.3
B8: ….қайта баҳолаш бўйича | L8: =SUM(D8:K8) -> 0
B9: ….балансдан чиқарилган | L9: =SUM(D9:K9) -> 0
B10: ….сотилган | F10: 4274.9 | L10: =SUM(D10:K10) -> 4274.9
B11: ….бошқа филиалга берилган | L11: =SUM(D11:K11) -> 0
B12: ….бошқа ҳисоб рақамга ўтказилган | K12: 99383.4 | L12: =SUM(D12:K12) -> 99383.4
B13: ….бошқа(нотўғри ўтказма-сторно) | L13: =SUM(D13:K13) -> 0
A14: в) | B14: кирими | C14: =SUM(C15:C18) -> 0 | E14: =SUM(E15:E18) -> 0 | F14: =SUM(F15:F18) -> 0 | G14: =SUM(G15:G18) -> 7699.3 | H14: =SUM(H15:H18) -> 0 | I14: =SUM(I15:I18) -> 91684.1 | J14: =SUM(J15:J18) -> 0 | K14: =SUM(K15:K18) -> 99383.4 | L14: =SUM(L15:L18) -> 198766.8
B15: ….қайта баҳолаш бўйича | L15: =SUM(D15:K15) -> 0
B16: ….сотиб олинган | G16: =1118.4+3610.9+2970 -> 7699.3 | I16: 91684.1 | K16: 99383.4 | L16: =SUM(D16:K16) -> 198766.8
B17: ….бошқа ҳисоб рақамдан ўтказилган | L17: =SUM(D17:K17) -> 0
B18: ….бошқа(нотўғри ўтказма-сторно) | L18: =SUM(D18:K18) -> 0
A19: г) | B19: =""&(Шаблон!B15)&" ҳолатига қолдиқ" -> 2024 йил 1 январ ҳолатига қолдиқ | C19: =SUM(C6+C14-C7) -> 0 | D19: =SUM(D6+D14-D7) -> 4016869.6 | E19: =SUM(E6+E14-E7) -> 0 | F19: =SUM(F6+F14-F7) -> 806644.43 | G19: =SUM(G6+G14-G7) -> 2756497.8 | H19: =SUM(H6+H14-H7) -> 0 | I19: =SUM(I6+I14-I7) -> 3299965.3 | J19: =SUM(J6+J14-J7) -> 0 | K19: =SUM(K6+K14-K7) -> 64039.594 | L19: =SUM(C19:K19) -> 10944017
A20: д) | B20: ўзгариш | C20: =C19-C6 -> 0 | D20: =D19-D6 -> 0 | E20: =E19-E6 -> 0 | F20: =F19-F6 -> -4274.9 | G20: =G19-G6 -> 7699.3 | H20: =H19-H6 -> 0 | I20: =I19-I6 -> 91684.1 | J20: =J19-J6 -> 0 | K20: =K19-K6 -> 0 | L20: =SUM(C20:K20) -> 95108.5
A21: II | B21: Аммортизация ажратмаси
A22: а) | B22: =""&(Шаблон!B16)&" ҳолатига қолдиқ" -> 2023 йил 1 январ ҳолатига қолдиқ | D22: =SUM(SUMIF(Баланс!$A:$A,16511,Баланс!$D:$D)/1000,0) -> 1023955.3 | E22: =SUM(SUMIF(Баланс!$A:$A,16519,Баланс!$D:$D)/1000,0) -> 0 | F22: =SUM(SUMIF(Баланс!$A:$A,16531,Баланс!$D:$D)/1000,0) -> 564853.11 | G22: =SUM(SUMIF(Баланс!$A:$A,16539,Баланс!$D:$D)/1000,0) -> 1551807.4 | H22: =SUM(SUMIF(Баланс!$A:$A,16605,Баланс!$D:$D)/1000,0) -> 0 | I22: =SUM(SUMIF(Баланс!$A:$A,16543,Баланс!$D:$D)/1000,0) -> 1063569.7 | J22: =SUM(SUMIF(Баланс!$A:$A,16551,Баланс!$D:$D)/1000,0) -> 0 | K22: 0 | L22: =SUM(D22:K22) -> 4204185.5
A23: б) | B23: =""&(Шаблон!B15)&" ҳолатига қолдиқ" -> 2024 йил 1 январ ҳолатига қолдиқ | D23: =SUM(SUMIF(Баланс!$A:$A,16511,Баланс!$H:$H)/1000,0) -> 1185560.3 | E23: =SUM(SUMIF(Баланс!$A:$A,16519,Баланс!$H:$H)/1000,0) -> 0 | F23: =SUM(SUMIF(Баланс!$A:$A,16531,Баланс!$H:$H)/1000,0) -> 655002.42 | G23: =SUM(SUMIF(Баланс!$A:$A,16539,Баланс!$H:$H)/1000,0) -> 2405110.9 | H23: =SUM(SUMIF(Баланс!$A:$A,16605,Баланс!$H:$H)/1000,0) -> 0 | I23: =SUM(SUMIF(Баланс!$A:$A,16543,Баланс!$H:$H)/1000,0) -> 3495483 | J23: =SUM(SUMIF(Баланс!$A:$A,16551,Баланс!$H:$H)/1000,0) -> 0 | K23: 0 | L23: =SUM(D23:K23) -> 7741156.7
A24: в) | B24: ўзгариш | D24: =D23-D22 -> 161605.06 | E24: =E23-E22 -> 0 | F24: =F23-F22 -> 90149.306 | G24: =G23-G22 -> 853303.47 | H24: =H23-H22 -> 0 | I24: =I23-I22 -> 2431913.3 | J24: =J23-J22 -> 0 | K24: =K23-K22 -> 0 | L24: =SUM(D24:K24) -> 3536971.2
A25: III | B25: Соф баланс қолдиғи
A26: а) | B26: =""&(Шаблон!B16)&" ҳолатига қолдиқ" -> 2023 йил 1 январ ҳолатига қолдиқ | D26: =D6-D22 -> 2992914.4 | E26: =E6-E22 -> 0 | F26: =F6-F22 -> 246066.22 | G26: =G6-G22 -> 1196991.1 | H26: =H6-H22 -> 0 | I26: =I6-I22 -> 2144711.5 | J26: =J6-J22 -> 0 | K26: =K6-K22 -> 64039.594 | L26: =SUM(D26:K26) -> 6644722.7
A27: б) | B27: =""&(Шаблон!B15)&" ҳолатига қолдиқ" -> 2024 йил 1 январ ҳолатига қолдиқ | D27: =D19-D23 -> 2831309.3 | E27: =E19-E23 -> 0 | F27: =F19-F23 -> 151642.01 | G27: =G19-G23 -> 351386.93 | H27: =H19-H23 -> 0 | I27: =I19-I23 -> -195517.76 | J27: =J19-J23 -> 0 | K27: =K19-K23 -> 64039.594 | L27: =SUM(D27:K27) -> 3202860.1
B30: =""&(Шаблон!B1)&"нинг Ички Аудит" -> АТ "Халқ банк"нинг Ички Аудит
B31: Департаменти бўлим бошлиғи: | H31: =+Шаблон!B13 -> А.Ҳазратқулов
B33: =""&(Шаблон!B1)&" "&(Шаблон!B2)&" вилояти" -> АТ "Халқ банк" Фаргона вилояти вилояти
B34: =""&(Шаблон!B3)&" филиал бошқарувчиси:" -> Бешариқ филиали филиал бошқарувчиси: | H34: =Шаблон!B5 -> _____________
B36: Бош бухгалтери: | H36: =Шаблон!B8 -> _____________

Sheet 9.мажбурият
G1: 9-жадвал
A2: =""&(Шаблон!B1&"нинг "&(Шаблон!B2)&" "&(Шаблон!B3)&" филиали бўйича "&(Шаблон!B15)&" ҳолатига мажбуриятлар ТАҲЛИЛИ") -> АТ "Халқ банк"нинг Фаргона вилояти Бешариқ филиали филиали бўйича 2024 йил 1 январ ҳолатига мажбуриятлар ТАҲЛИЛИ
G3: (минг сўмда)
A4: Т/Р | B4: Мажбуриятлар таркиби | C4: =""&(Шаблон!B16)&" ҳолатига" -> 2023 йил 1 январ ҳолатига | E4: =""&(Шаблон!B15)&" ҳолатига" -> 2024 йил 1 январ ҳолатига | G4: фарқи (+;-)
C6: Сумма | D6: Фоизи | E6: Сумма | F6: Фоизи
A7: I | B7: Талаб қилиб олингунча депозитлар | C7: =SUM(SUMIF(Баланс!$B:$B,20200,Баланс!$D:$D)/1000,0) -> 8765481 | D7: =SUM(C7/C26*100) -> 2.3400438 | E7: =SUM(SUMIF(Баланс!$B:$B,20200,Баланс!$H:$H)/1000,0) -> 12015427 | F7: =SUM(E7/E26*100) -> 2.9319325 | G7: =E7-C7 -> 3249946.4
A8: а) | B8: Шундан жисмоний шахсларнинг талаб қилиб олгунча депозитлари | C8: =SUM(SUMIF(Баланс!$A:$A,20206,Баланс!$D:$D)/1000,0) -> 20121.107 | D8: =SUM(C8/C7*100) -> 0.22954938 | E8: =SUM(SUMIF(Баланс!$A:$A,20206,Баланс!$H:$H)/1000,0) -> 30047.117 | F8: =SUM(E8/E7*100) -> 0.25007114 | G8: =E8-C8 -> 9926.0097
A9: II | B9: Жамғарма депозитлар | C9: =SUM(SUMIF(Баланс!$B:$B,20400,Баланс!$D:$D)/1000,0) -> 12715184 | D9: =SUM(C9/C26*100) -> 3.3944614 | E9: =SUM(SUMIF(Баланс!$B:$B,20400,Баланс!$H:$H)/1000,0) -> 10711867 | F9: =SUM(E9/E26*100) -> 2.6138455 | G9: =E9-C9 -> -2003316.7
A10: а) | B10: Шундан жисмоний шахсларнинг жамғарма депозитлари | C10: =SUM(SUMIF(Баланс!$A:$A,20406,Баланс!$D:$D)/1000,0) -> 12715184 | D10: =C10/C9*100 -> 100 | E10: =SUM(SUMIF(Баланс!$A:$A,20406,Баланс!$H:$H)/1000,0) -> 10711867 | F10: =E10/E9*100 -> 100 | G10: =E10-C10 -> -2003316.7
A11: III | B11: Муддатли депозитлар | C11: =SUM(SUMIF(Баланс!$B:$B,20600,Баланс!$D:$D)/1000,0) -> 37405544 | D11: =SUM(C11/C26*100) -> 9.9858311 | E11: =SUM(SUMIF(Баланс!$B:$B,20600,Баланс!$H:$H)/1000,0) -> 34323238 | F11: =SUM(E11/E26*100) -> 8.3753505 | G11: =E11-C11 -> -3082305.5
A12: а) | B12: Шундан жисмоний шахсларнинг муддатли депозитлари | C12: =SUM(SUMIF(Баланс!$A:$A,20606,Баланс!$D:$D)/1000,0) -> 14780544 | D12: =C12/C11*100 -> 39.514313 | E12: =SUM(SUMIF(Баланс!$A:$A,20606,Баланс!$H:$H)/1000,0) -> 13498238 | F12: =E12/E11*100 -> 39.32682 | G12: =E12-C12 -> -1282305.5
A13: IV | B13: Бошқа банкларга тўланиши лозим бўлган маблағлар | C13: =SUM(SUMIF(Баланс!$B:$B,21000,Баланс!$D:$D)/1000,0) -> 205551.75 | D13: =SUM(C13/C26*100) -> 0.054874354 | E13: =SUM(SUMIF(Баланс!$B:$B,21000,Баланс!$H:$H)/1000,0) -> 805969.81 | F13: =SUM(E13/E26*100) -> 0.19666791 | G13: =E13-C13 -> 600418.06
A14: V | B14: Олинган қисқа ва узоқ муддатли ссудалар | C14: =SUM(SUMIF(Баланс!$B:$B,21600,Баланс!$D:$D)/1000+SUMIF(Баланс!$B:$B,22000,Баланс!$D:$D)/1000,0) -> 13342 | D14: =SUM(C14/C26*100) -> 0.0035617971 | E14: =SUM(SUMIF(Баланс!$B:$B,21600,Баланс!$H:$H)/1000+SUMIF(Баланс!$B:$B,22000,Баланс!$H:$H)/1000,0) -> 0 | F14: =SUM(E14/E26*100) -> 0 | G14: =E14-C14 -> -13342
A15: VI | B15: Лизинг тўловлари бўйича мажбуриятлар | C15: =SUM(SUMIF(Баланс!$B:$B,22100,Баланс!$D:$D)/1000,0) -> 0 | D15: =SUM(C15/C26*100) -> 0 | E15: =SUM(SUMIF(Баланс!$B:$B,22100,Баланс!$H:$H)/1000,0) -> 0 | F15: =SUM(E15/E26*100) -> 0 | G15: =E15-C15 -> 0
A16: VII | B16: Бошқа банк(филиаллар)га тўланган маблағлар | C16: =SUM(SUMIF(Баланс!$B:$B,22200,Баланс!$D:$D)/1000,0) -> 1.7824803e+08 | D16: =SUM(C16/C26*100) -> 47.585318 | E16: =SUM(SUMIF(Баланс!$B:$B,22200,Баланс!$H:$H)/1000,0) -> 1.9170214e+08 | F16: =SUM(E16/E26*100) -> 46.778006 | G16: =E16-C16 -> 13454114
A17: VIII | B17: Мажбуриятлар бўйича ҳисобланган фоизлар | C17: =SUM(SUMIF(Баланс!$B:$B,22400,Баланс!$D:$D)/1000,0) -> 465238.6 | D17: =SUM(C17/C26*100) -> 0.12420068 | E17: =SUM(SUMIF(Баланс!$B:$B,22400,Баланс!$H:$H)/1000,0) -> 308921.65 | F17: =SUM(E17/E26*100) -> 0.075381206 | G17: =E17-C17 -> -156316.96
A18: IX | B18: Тўлаш учун ҳисобланган солиқлар | C18: =SUM(SUMIF(Баланс!$B:$B,22500,Баланс!$D:$D)/1000,0) -> 257420.33 | D18: =SUM(C18/C26*100) -> 0.068721256 | E18: =SUM(SUMIF(Баланс!$B:$B,22500,Баланс!$H:$H)/1000,0) -> 443937.65 | F18: =SUM(E18/E26*100) -> 0.108327 | G18: =E18-C18 -> 186517.32 | J18: =+E9+E11+E16+E19 -> 3.9449059e+08 | K18: =+J18/E26*100 -> 96.261226
A19: X | B19: Мижозларнинг бошқа депозитлари | C19: =SUM(SUMIF(Баланс!$B:$B,22600,Баланс!$D:$D)/1000,0) -> 1.3462847e+08 | D19: =SUM(C19/C26*100) -> 35.940586 | E19: =SUM(SUMIF(Баланс!$B:$B,22600,Баланс!$H:$H)/1000,0) -> 1.5775334e+08 | F19: =SUM(E19/E26*100) -> 38.494024 | G19: =E19-C19 -> 23124871 | J19: =+E16+E19 -> 3.4945549e+08 | K19: =+J19/J18*100 -> 88.583985
A20: XI | B20: Клиринг трансакциялари | C20: =SUM(SUMIF(Баланс!$B:$B,23200,Баланс!$D:$D)/1000,0) -> 0 | D20: =SUM(C20/C26*100) -> 0 | E20: =SUM(SUMIF(Баланс!$B:$B,23200,Баланс!$H:$H)/1000,0) -> 0 | F20: =SUM(E20/E26*100) -> 0 | G20: =E20-C20 -> 0
A21: XII | B21: Ҳукуматга тегишли даромад ва бошқа тушумлар | C21: =SUM(SUMIF(Баланс!$B:$B,23400,Баланс!$D:$D)/1000,0) -> 0 | D21: =SUM(C21/C26*100) -> 0 | E21: =SUM(SUMIF(Баланс!$B:$B,23400,Баланс!$H:$H)/1000,0) -> 0 | F21: =SUM(E21/E26*100) -> 0 | G21: =E21-C21 -> 0
A22: XIII | B22: Мижозларнинг пластик карталарига ўтказилиши лозим бўлган маблағлари | C22: =SUM(SUMIF(Баланс!$B:$B,23100,Баланс!$D:$D)/1000,0) -> 10553.727 | D22: =SUM(C22/C26*100) -> 0.0028174363 | E22: =SUM(SUMIF(Баланс!$B:$B,23100,Баланс!$H:$H)/1000,0) -> 35112.843 | F22: =SUM(E22/E26*100) -> 0.0085680252 | G22: =E22-C22 -> 24559.116
A23: XIV | B23: Хўжалик юритувчи субъектларнинг ва банкнинг транзит ҳисоб рақамларига мижозларнинг пластик карталардан келиб тушган маблағлари | C23: =SUM(SUMIF(Баланс!$B:$B,23500,Баланс!$D:$D)/1000,0) -> 450087.01 | D23: =SUM(C23/C26*100) -> 0.12015579 | E23: =SUM(SUMIF(Баланс!$B:$B,23500,Баланс!$H:$H)/1000,0) -> 410027.19 | F23: =SUM(E23/E26*100) -> 0.10005237 | G23: =E23-C23 -> -40059.816
A24: XV | B24: Чиқарилган жамғарма сертификатлари | C24: =SUM(SUMIF(Баланс!$B:$B,23600,Баланс!$D:$D)/1000,0)+SUM(SUMIF(Баланс!$B:$B,23700,Баланс!$D:$D)/1000,0)+SUM(SUMIF(Баланс!$B:$B,22300,Баланс!$D:$D)/1000,0) -> 0 | D24: =SUM(C24/C26*100) -> 0 | E24: =SUM(SUMIF(Баланс!$B:$B,23600,Баланс!$H:$H)/1000,0)+SUM(SUMIF(Баланс!$B:$B,23700,Баланс!$H:$H)/1000,0)+SUM(SUMIF(Баланс!$B:$B,22300,Баланс!$H:$H)/1000,0) -> 0 | F24: =SUM(E24/E26*100) -> 0 | G24: =E24-C24 -> 0
A25: XVI | B25: Бошқа мажбуриятлар | C25: =SUM(SUMIF(Баланс!$B:$B,29800,Баланс!$D:$D)/1000+SUMIF(Баланс!$B:$B,22800,Баланс!$D:$D)/1000,0) -> 1421283.2 | D25: =SUM(C25/C26*100) -> 0.37942756 | E25: =SUM(SUMIF(Баланс!$B:$B,29800,Баланс!$H:$H)/1000+SUMIF(Баланс!$B:$B,22800,Баланс!$H:$H)/1000,0) -> 1302569.2 | F25: =SUM(E25/E26*100) -> 0.31784511 | G25: =E25-C25 -> -118714.08
B26: Жами мажбуриятлар | C26: =C7+C9+C11+C14+C15+C16+C17+C18+C19+C20+C21+C22+C23+C24+C25+C13 -> 3.7458619e+08 | D26: =D7+D9+D11+D14+D15+D16+D17+D18+D19+D20+D21+D22+D23+D24+D25+D13 -> 100 | E26: =E7+E9+E11+E14+E15+E16+E17+E18+E19+E20+E21+E22+E23+E24+E25+E13 -> 4.0981256e+08 | F26: =F7+F9+F11+F14+F15+F16+F17+F18+F19+F20+F21+F22+F23+F24+F25+F13 -> 100 | G26: =G7+G9+G11+G14+G15+G16+G17+G18+G19+G20+G21+G22+G23+G24+G25+G13 -> 35226371
C27: =117279009877.36/1000 -> 1.1727901e+08 | E27: =128851614609.27/1000 -> 1.2885161e+08
B28: =""&(Шаблон!B1)&"нинг Ички аудит" -> АТ "Халқ банк"нинг Ички аудит | C28: =+C26-C27 -> 2.5730718e+08 | E28: =+E26-E27 -> 2.8096094e+08
B29: департаменти бош мутахассиси: | F29: =Шаблон!B13 -> А.Ҳазратқулов
B31: =""&(Шаблон!B1)&" "&(Шаблон!B2)&"" -> АТ "Халқ банк" Фаргона вилояти
B32: =""&(Шаблон!B3)&" бошқарувчиси:" -> Бешариқ филиали бошқарувчиси: | F32: =Шаблон!B5 -> _____________
B34: Бош бухгалтери: | F34: =Шаблон!B8 -> _____________

Sheet 15.капитал
H1: 15-жадвал
A2: =""&(Шаблон!B1)&"нинг "&(Шаблон!B2)&""&(Шаблон!B3)&" филиали капиталининг "&(Шаблон!B15)&" ҳолатига ТАҲЛИЛИ" -> АТ "Халқ банк"нинг Фаргона вилоятиБешариқ филиали филиали капиталининг 2024 йил 1 январ ҳолатига ТАҲЛИЛИ
H3: (минг сўмда)
A4: Т/Р | B4: Капитал таркиби | C4: =""&(Шаблон!B16)&" ҳолатига" -> 2023 йил 1 январ ҳолатига | E4: =""&(Шаблон!B15)&" ҳолатига" -> 2024 йил 1 январ ҳолатига | G4: фарқи (+;-) | H4: Изоҳ
C5: сумма | D5: фоизи | E5: сумма | F5: фоизи
A6: А | B6: Б | C6: 1 | D6: 2 | E6: 3 | F6: 4 | G6: 5 | H6: 6
A7: 1 | B7: Акционерлик капитали | C7: =SUM(SUMIF(Баланс!$B:$B,30300,Баланс!$D:$D)/1000,0) -> 0 | D7: =C7/C11*100 -> 0 | E7: =SUM(SUMIF(Баланс!$B:$B,30300,Баланс!$H:$H)/1000,0) -> 0 | F7: =E7/E11*100 -> 0 | G7: =SUM(E7-C7) -> 0
A8: =A7+1 -> 2 | B8: Қўшимча капитал | C8: =SUM(SUMIF(Баланс!$B:$B,30600,Баланс!$D:$D)/1000,0) -> 0 | D8: =C8/C11*100 -> 0 | E8: =SUM(SUMIF(Баланс!$B:$B,30600,Баланс!$H:$H)/1000,0) -> 0 | F8: =E8/E11*100 -> 0 | G8: =SUM(E8-C8) -> 0
A9: =A8+1 -> 3 | B9: Заҳира капитали | C9: =SUM(SUMIF(Баланс!$B:$B,30900,Баланс!$D:$D)/1000,0) -> 149894.13 | D9: =C9/C11*100 -> 0.76566198 | E9: =SUM(SUMIF(Баланс!$B:$B,30900,Баланс!$H:$H)/1000,0) -> 139434.02 | F9: =E9/E11*100 -> 0.54821807 | G9: =SUM(E9-C9) -> -10460.115
A10: =A9+1 -> 4 | B10: Тақсимланмаган фойда | C10: =SUM(SUMIF(Баланс!$B:$B,31200,Баланс!$D:$D)/1000,0) -> 19427170 | D10: =C10/C11*100 -> 99.234338 | E10: =SUM(SUMIF(Баланс!$B:$B,31200,Баланс!$H:$H)/1000,0) -> 25294609 | F10: =E10/E11*100 -> 99.451782 | G10: =SUM(E10-C10) -> 5867439.1
B11: Жами капитал | C11: =SUM(C7:C10) -> 19577064 | D11: =SUM(D7:D10) -> 100 | E11: =SUM(E7:E10) -> 25434043 | F11: =SUM(F7:F10) -> 100 | G11: =SUM(E11-C11) -> 5856978.9 | H11: х
E12: =+E11+'1.активлар'!E30 -> 4.985791e+08
B14: =""&(Шаблон!B1)&"нинг Ички аудит" -> АТ "Халқ банк"нинг Ички аудит
B15: департаменти бош мутахассиси: | G15: =Шаблон!B13 -> А.Ҳазратқулов
B17: =""&(Шаблон!B1)&" "&(Шаблон!B2)&"" -> АТ "Халқ банк" Фаргона вилояти
B18: =""&(Шаблон!B3)&" бошқарувчиси:" -> Бешариқ филиали бошқарувчиси: | G18: =Шаблон!B5 -> _____________
B20: Бош бухгалтери: | G20: =Шаблон!B8 -> _____________

Sheet 17.смета
I1: 17-жадвал
A2: =""&(Шаблон!B1)&"нинг "&(Шаблон!B2)&""&(Шаблон!B3)&" филиали томонидан олинган даромад ва қилинган харажатлар таҳлили, ҳамда сметасига амал қилиниши тўғрисида "&(Шаблон!B15)&" ҳолатига" -> АТ "Халқ банк"нинг Фаргона вилоятиБешариқ филиали филиали томонидан олинган даромад ва қилинган харажатлар таҳлили, ҳамда сметасига амал қилиниши тўғрисида 2024 йил 1 январ ҳолатига
C3: М А Ъ Л У М О Т
I4: (минг сўмда)
A5: Т/Р | B5: Даромад ва харажатлар таркиби | C5: =""&(Шаблон!B16)&" ҳолатига" -> 2023 йил 1 январ ҳолатига | E5: =""&(Шаблон!B15)&" ҳолатига" -> 2024 йил 1 январ ҳолатига | G5: Ўтган йилга нисбатан фарқи (+;-) | H5: =""&(Шаблон!B15)&" ҳолатига смета бўйича" -> 2024 йил 1 январ ҳолатига смета бўйича | I5: Сметага нисбатан фарқи (+;-)
C6: Сумма | D6: Фоизи | E6: Сумма | F6: Фоизи
A7: A | B7: Б | C7: 1 | D7: 2 | E7: 3 | F7: 4 | G7: 5 | H7: 6 | I7: 7
A8: 1 | B8: Фоизли даромадлар | C8: =N75 -> 8358260.3 | D8: =C8/C10*100 -> 51.073876 | E8: =O75 -> 9751091.3 | F8: =E8/E10*100 -> 61.377514 | G8: =E8-C8 -> 1392831 | H8: 0 | I8: =E8-H8 -> 9751091.3 | K8: =1371202757.93/1000 -> 1371202.8 | L8: =+K8/E8*100 -> 14.062044 | M8: =+E8-K8 -> 8379888.6
A9: 2 | B9: Фоизсиз даромадлар | C9: =Q75 -> 8006779.7 | D9: =C9/C10*100 -> 48.926124 | E9: =R75 -> 6135983.1 | F9: =E9/E10*100 -> 38.622486 | G9: =E9-C9 -> -1870796.6 | H9: 0 | I9: =E9-H9 -> 6135983.1
B10: Жами даромад | C10: =C8+C9 -> 16365040 | D10: =D8+D9 -> 100 | E10: =E8+E9 -> 15887074 | F10: =F8+F9 -> 100 | G10: =G8+G9 -> -477965.53 | H10: =H8+H9 -> 0 | I10: =I8+I9 -> 15887074 | K10: =+K8 -> 1371202.8 | L10: =+K10/E10*100 -> 8.630933 | M10: =+E10-K10 -> 14515872
A11: 3 | B11: Фоизли харажатлар | C11: =T75 -> 5246960.4 | D11: =C11/C24*100 -> 35.898816 | E11: =U75 -> 5927005.9 | F11: =E11/E24*100 -> 37.649809 | G11: =E11-C11 -> 680045.46 | H11: 0 | I11: =E11-H11 -> 5927005.9 | K11: =1371203397.23/1000 -> 1371203.4 | L11: =+K11/E11*100 -> 23.134841
A12: 4 | B12: Фоизсиз харажатлар | C12: =W75 -> 75764.996 | D12: =C12/C24*100 -> 0.51837129 | E12: =X75 -> 780288 | F12: =E12/E24*100 -> 4.9565826 | G12: =E12-C12 -> 704523 | H12: 0 | I12: =E12-H12 -> 780288
A13: 5 | B13: Операцион харажатлар | C13: =SUM(C15:C21) -> 3683732.1 | D13: =C13/C24*100 -> 25.203472 | E13: =SUM(E15:E21) -> 7184701.5 | F13: =E13/E24*100 -> 45.639003 | G13: =SUM(G15:G21) -> 3500969.4 | H13: =SUM(H15:H21) -> 0 | I13: =E13-H13 -> 7184701.5
B14: Шундан:
A15: а | B15: Иш хақи | C15: =SUM(SUMIF(Баланс!$B:$B,56100,Баланс!$C:$C)/1000,0) -> 2518462.8 | D15: =C15/C13*100 -> 68.367154 | E15: =SUM(SUMIF(Баланс!$B:$B,56100,Баланс!$G:$G)/1000,0) -> 4932721.4 | F15: =E15/E13*100 -> 68.655899 | G15: =E15-C15 -> 2414258.5 | H15: 0 | I15: =E15-H15 -> 4932721.4
A16: б | B16: Ижара ва сақлаш харажати | C16: =SUM(SUMIF(Баланс!$B:$B,56200,Баланс!$C:$C)/1000,0) -> 420490.75 | D16: =C16/C13*100 -> 11.414803 | E16: =SUM(SUMIF(Баланс!$B:$B,56200,Баланс!$G:$G)/1000,0) -> 1249884.5 | F16: =E16/E13*100 -> 17.396471 | G16: =E16-C16 -> 829393.77 | H16: 0 | I16: =E16-H16 -> 1249884.5
A17: в | B17: Транспорт ва сафар харажатлари | C17: =SUM(SUMIF(Баланс!$B:$B,56300,Баланс!$C:$C)/1000,0) -> 67783.48 | D17: =C17/C13*100 -> 1.8400763 | E17: =SUM(SUMIF(Баланс!$B:$B,56300,Баланс!$G:$G)/1000,0) -> 155556.96 | F17: =E17/E13*100 -> 2.1651137 | G17: =E17-C17 -> 87773.478 | H17: 0 | I17: =E17-H17 -> 155556.96
A18: г | B18: Маъмурий харажатлар | C18: =SUM(SUMIF(Баланс!$B:$B,56400,Баланс!$C:$C)/1000,0) -> 273379.92 | D18: =C18/C13*100 -> 7.4212759 | E18: =SUM(SUMIF(Баланс!$B:$B,56400,Баланс!$G:$G)/1000,0) -> 140311.78 | F18: =E18/E13*100 -> 1.9529243 | G18: =E18-C18 -> -133068.15 | H18: 0 | I18: =E18-H18 -> 140311.78
A19: д | B19: Тақдимот ва хайрия | C19: =SUM(SUMIF(Баланс!$B:$B,56500,Баланс!$C:$C)/1000,0) -> 0 | D19: =C19/C13*100 -> 0 | E19: =SUM(SUMIF(Баланс!$B:$B,56500,Баланс!$G:$G)/1000,0) -> 0 | F19: =E19/E13*100 -> 0 | G19: =E19-C19 -> 0 | H19: 0 | I19: =E19-H19 -> 0
A20: е | B20: Эскириш харажатлари | C20: =SUM(SUMIF(Баланс!$B:$B,56600,Баланс!$C:$C)/1000,0) -> 381650.81 | D20: =C20/C13*100 -> 10.360439 | E20: =SUM(SUMIF(Баланс!$B:$B,56600,Баланс!$G:$G)/1000,0) -> 593218.78 | F20: =E20/E13*100 -> 8.2566935 | G20: =E20-C20 -> 211567.97 | H20: 0 | I20: =E20-H20 -> 593218.78
A21: ё | B21: Суғурта, солиқ ва бошқа хар. | C21: =SUM(SUMIF(Баланс!$B:$B,56700,Баланс!$C:$C)/1000,0) -> 21964.329 | D21: =C21/C13*100 -> 0.59625206 | E21: =SUM(SUMIF(Баланс!$B:$B,56700,Баланс!$G:$G)/1000,0) -> 113008.09 | F21: =E21/E13*100 -> 1.5728989 | G21: =E21-C21 -> 91043.761 | H21: 0 | I21: =E21-H21 -> 113008.09
A22: 6 | B22: Келгуси зарарларни баҳолаш | C22: =SUM(SUMIF(Баланс!$B:$B,56800,Баланс!$C:$C)/1000,0) -> 5609513.3 | D22: =C22/C24*100 -> 38.379341 | E22: =SUM(SUMIF(Баланс!$B:$B,56800,Баланс!$G:$G)/1000,0) -> 1850464 | F22: =E22/E24*100 -> 11.754606 | G22: =E22-C22 -> -3759049.3 | H22: 0 | I22: =E22-H22 -> 1850464
A23: 7 | B23: Даромад солиғи | C23: =SUM(SUMIF(Баланс!$B:$B,56900,Баланс!$C:$C)/1000,0) -> 0 | D23: =C23/C24*100 -> 0 | E23: =SUM(SUMIF(Баланс!$B:$B,56900,Баланс!$G:$G)/1000,0) -> 0 | F23: =E23/E24*100 -> 0 | G23: =E23-C23 -> 0 | H23: 0 | I23: =E23-H23 -> 0
B24: Жами харажатлар | C24: =C11+C12+C13+C23+C22 -> 14615971 | D24: =D13+D12+D11+D22+D23 -> 100 | E24: =E11+E12+E13+E23+E22 -> 15742459 | F24: =F13+F12+F11+F22+F23 -> 100 | G24: =G11+G12+G13+G23+G22 -> 1126488.5 | H24: =H13+H12+H11+H22+H23 -> 0 | I24: =SUM(I11:I13)+I22+I23 -> 15742459 | K24: 19211519
B25: Фойда | C25: =C10-C24 -> 1749069.2 | D25: х | E25: =E10-E24 -> 144615.13 | F25: х | G25: =E25-C25 -> -1604454.1 | H25: =+H10-H24 -> 0 | I25: =I10-I24 -> 144615.13 | K25: =+K24-C10 -> 2846479.3
B26: Ҳисобланган, лекин ундирилмаган фоиз ва хизматлар | C26: =SUM(SUMIF(Баланс!$B:$B,16300,Баланс!$C:$C)/1000+SUMIF(Баланс!$B:$B,16400,Баланс!$C:$C)/1000,0) -> 12488981 | D26: х | E26: =SUM(SUMIF(Баланс!$B:$B,16300,Баланс!$G:$G)/1000+SUMIF(Баланс!$B:$B,16400,Баланс!$G:$G)/1000,0) -> 21636700 | F26: =E26/E27*100 -> -100.67288 | G26: =E26-C26 -> 9147718.7 | H26: 0 | I26: =H26-E26 -> -21636700
B27: Реал соф фойда | C27: =C25-C26 -> -10739912 | D27: =C27/C25*100 -> -614.03583 | E27: =E25-E26 -> -21492085 | F27: =E27/E25*100 -> -14861.574 | G27: =E27-C27 -> -10752173 | H27: =H25-H26 -> 0 | I27: =E27-H27 -> -21492085
B28: Харажатнинг даромаддаги улуши | C28: =C24/C10*100 -> 89.31216 | D28: =SUM(D26:D27) -> -614.03583 | E28: =E24/E10*100 -> 99.089731 | F28: =SUM(F26:F27) -> -14962.246 | G28: =G24/G10*100 -> -235.68405 | H28: =H24/H10*100 -> #DIV/0! | I28: =+I27/E27*100 -> 100
B29: НПС | C29: =97156801.41/1000 -> 97156.801 | E29: =+K8 -> 1371202.8
C30: =+C27-C29 -> -10837069 | E30: =+K11 -> 1371203.4
E31: =+E25-E29+E30 -> 144615.77
E32: =+E31-E26 -> -21492084
C33: 11674206 | E33: =+E25-E26 -> -21492085
B34: =""&(Шаблон!B1)&"нинг Самарқанд вилоят филиали" -> АТ "Халқ банк"нинг Самарқанд вилоят филиали | C34: =+C33-C24 -> -2941765.2 | E34: =+E10-E24 -> 144615.13
B35: Якуний назорат бўлим бош мутахассиси: | C35: =+C24/C10*100 -> 89.31216 | E35: =+E24/E10*100 -> 99.089731 | F35: =Шаблон!B13 -> А.Ҳазратқулов
B37: =""&(Шаблон!B1)&" "&(Шаблон!B2)&"" -> АТ "Халқ банк" Фаргона вилояти
B38: =""&(Шаблон!B3)&" филиал бошқарувчиси:" -> Бешариқ филиали филиал бошқарувчиси: | F38: =Шаблон!B5 -> _____________
B40: Бош бухгалтери: | F40: =Шаблон!B8 -> _____________
M42: Фоизли даромадлар | P42: Фоизсиз даромадлар | S42: Фоизли харажатлар | V42: Фоизсиз харажатлар
M43: 40200 | N43: =SUM(SUMIF(Баланс!$B:$B,M43,Баланс!$D:$D)/1000,0) -> 0 | O43: =SUM(SUMIF(Баланс!$B:$B,M43,Баланс!$H:$H)/1000,0) -> 0 | P43: 45200 | Q43: =SUM(SUMIF(Баланс!$B:$B,P43,Баланс!$D:$D)/1000,0) -> 1138018.1 | R43: =SUM(SUMIF(Баланс!$B:$B,P43,Баланс!$H:$H)/1000,0) -> 2364709.9 | S43: 50100 | T43: =SUM(SUMIF(Баланс!$B:$B,S43,Баланс!$C:$C)/1000,0) -> 0 | U43: =SUM(SUMIF(Баланс!$B:$B,S43,Баланс!$G:$G)/1000,0) -> 0 | V43: 55100 | W43: =SUM(SUMIF(Баланс!$B:$B,V43,Баланс!$C:$C)/1000,0) -> 56173.453 | X43: =ROUND(SUMIF(Баланс!$B:$B,V43,Баланс!$G:$G)/1000,0) -> 264575
...

Sheet 2.Мол.ёр.16102-1
L1: 2-жадвал
B2: =""&(Шаблон!B1)&"нинг "&(Шаблон!B2)&" вилоят "&(Шаблон!B3)&" филиали томонидан Халқ банк филиалларига берилган молиявий ёрдам ва унга ҳисобланган фоизларнинг ундирилиши бўйича 2016 йил 1 сентябр холатига" -> АТ "Халқ банк"нинг Фаргона вилояти вилоят Бешариқ филиали филиали томонидан Халқ банк филиалларига берилган молиявий ёрдам ва унга ҳисобланган фоизларнинг ундирилиши бўйича 2016 йил 1 сентябр холатига
B3: МАЪЛУМОТ
J4: сўмда
A5: Т.Р | B5: Санаси | C5: Қайтарилган ресурс маблағи | D5: Олинган ресурс маблағи | E5: Кун якунига колдик сумма | F5: Фоизи | G5: Кунлар сони | H5: Хисобланиши лозим фоиз суммаси | I5: Тўлаб берилган | J5: Фарқ(+,-)
A6: а | B6: 2 | C6: 3 | D6: 4 | E6: 5 | F6: 6 | G6: 7 | H6: 8 | I6: 9 | J6: 10
A7: Фаргон вилоят филиалига берилган ресурси
A8: 1 | B8: 26.01.2015 | C8: 0 | D8: 1700000000 | E8: =+D8-C8 -> 1700000000 | F8: 1 | G8: 1 | H8: =E8*F8%/365*G8 -> 46575.342
A9: =+A8+1 -> 2 | B9: 31.03.2015 | C9: 200000000 | D9: 0 | E9: =E8-C9+D9 -> 1500000000 | F9: 5 | G9: =+B10-B9 -> 7 | H9: =E9*F9%/365*G9 -> 1438356.2
A10: =+A9+1 -> 3 | B10: 07.04.2015 | C10: 200000000 | D10: 0 | E10: =E9-C10+D10 -> 1300000000 | F10: 5 | G10: =+B11-B10 -> 323 | H10: =E10*F10%/365*G10 -> 57520548
A11: =+A10+1 -> 4 | B11: 24.02.2016 | C11: 0 | D11: 2000000000 | E11: =E10-C11+D11 -> 3300000000 | F11: 5 | G11: =+B12-B11 -> 0 | H11: =E11*F11%/365*G11 -> 0
A12: =+A11+1 -> 5 | B12: 24.02.2016 | C12: 1300000000 | D12: 0 | E12: =E11-C12+D12 -> 2000000000 | F12: 5 | G12: =+B13-B12 -> 2 | H12: =E12*F12%/365*G12 -> 547945.21
A13: =+A12+1 -> 6 | B13: 26.02.2016 | C13: 0 | D13: 500000000 | E13: =E12-C13+D13 -> 2500000000 | F13: 5 | G13: =+B14-B13 -> 1 | H13: =E13*F13%/365*G13 -> 342465.75
A14: =+A13+1 -> 7 | B14: 27.02.2016 | C14: 0 | D14: 200000000 | E14: =E13-C14+D14 -> 2700000000 | F14: 5 | G14: =+B15-B14 -> 5 | H14: =E14*F14%/365*G14 -> 1849315.1
A15: =+A14+1 -> 8 | B15: 03.03.2016 | C15: 100000000 | D15: 0 | E15: =E14-C15+D15 -> 2600000000 | F15: 5 | G15: =+B16-B15 -> 2 | H15: =E15*F15%/365*G15 -> 712328.77
A16: =+A15+1 -> 9 | B16: 05.03.2016 | C16: 100000000 | D16: 0 | E16: =E15-C16+D16 -> 2500000000 | F16: 5 | G16: =+B17-B16 -> 4 | H16: =E16*F16%/365*G16 -> 1369863
A17: =+A16+1 -> 10 | B17: 09.03.2016 | C17: 0 | D17: 200000000 | E17: =E16-C17+D17 -> 2700000000 | F17: 5 | G17: =+B18-B17 -> 7 | H17: =E17*F17%/365*G17 -> 2589041.1
A18: =+A17+1 -> 11 | B18: 16.03.2016 | C18: 50000000 | D18: 0 | E18: =E17-C18+D18 -> 2650000000 | F18: 5 | G18: =+B19-B18 -> 11 | H18: =E18*F18%/365*G18 -> 3993150.7
A19: =+A18+1 -> 12 | B19: 27.03.2016 | C19: 0 | D19: 350000000 | E19: =E18-C19+D19 -> 3000000000 | F19: 5 | G19: =+B20-B19 -> 29 | H19: =E19*F19%/365*G19 -> 11917808
A20: =+A19+1 -> 13 | B20: 25.04.2016 | C20: 0 | D20: 500000000 | E20: =E19-C20+D20 -> 3500000000 | F20: 5 | G20: =+B21-B20 -> 5 | H20: =E20*F20%/365*G20 -> 2397260.3
... A33: =+A32+1 -> 26 | B33: 06.09.2016 | C33: 200000000 | D33: 0 | E33: =E32-C33+D33 -> 500000000 | F33: 5 | G33: =+B34-B33 -> 30 | H33: =E33*F33%/365*G33 -> 2054794.5
A34: =+A33+1 -> 27 | B34: 06.10.2016 | C34: 500000000 | D34: 0 | E34: =E33-C34+D34 -> 0 | F34: 5 | H34: =E34*F34%/365*G34 -> 0
A35: ЖАМИ Фаргон вилоят филиали ресурси | H35: =SUM(H8:H34) -> 1.1049178e+08 | I35: 66258904 | J35: =I35-H35 -> -44232877
A36: ХАММАСИ | H36: =+H35 -> 1.1049178e+08 | I36: =+I35 -> 66258904 | J36: =+J35 -> -44232877 | L36: -1402736.7
B38: =+'1.активлар'!B34 -> АТ "Халқ банк"нинг Ички аудит
B39: =+'1.активлар'!B35 -> департаменти бўлим бошлиғи: | F39: =+'1.активлар'!F35 -> А.Ҳазратқулов
B41: =+'1.активлар'!B37 -> АТ "Халқ банк" Фаргона вилояти
B42: =+'1.активлар'!B38 -> Бешариқ филиали бошқарувчиси: | F42: =+'1.активлар'!F38 -> _____________
B44: =+'1.активлар'!B40 -> Бош бухгалтери: | F44: =+'1.активлар'!F40 -> _____________

Sheet 2,1.Мол.ёр.22203-1
L1: 2-жадвал
B2: =""&(Шаблон!B1)&"нинг "&(Шаблон!B2)&" вилоят "&(Шаблон!B3)&" филиали томонидан Халқ банк филиалларидан олинган молиявий ёрдам ва унга ҳисобланган фоизларнинг ундирилиши бўйича 2020 йил 1 январ ҳолатига" -> АТ "Халқ банк"нинг Фаргона вилояти вилоят Бешариқ филиали филиали томонидан Халқ банк филиалларидан олинган молиявий ёрдам ва унга ҳисобланган фоизларнинг ундирилиши бўйича 2020 йил 1 январ ҳолатига
B3: МАЪЛУМОТ
J4: сўмда
A5: Т.Р | B5: Санаси | C5: Қайтарилган ресурс маблағи | D5: Олинган ресурс маблағи | E5: Кун якунига колдик сумма | F5: Фоизи | G5: Кунлар сони | H5: Хисобланиши лозим фоиз суммаси | I5: Тўлаб берилган | J5: Фарқ(+,-)
A6: а | B6: 2 | C6: 3 | D6: 4 | E6: 5 | F6: 6 | G6: 7 | H6: 8 | I6: 9 | J6: 10
A7: Бош банкдан олинган 8 фоизли ресурс маблаглари
A8: 1 | B8: 01.12.2017 | C8: 0 | D8: 4191220000 | E8: =+D8-C8 -> 4191220000 | F8: 8 | G8: =B9-B8 -> 3 | H8: =E8*F8%/365*G8 -> 2755870.7
A9: =+A8+1 -> 2 | B9: 04.12.2017 | C9: 0 | D9: 1500000000 | E9: =E8-C9+D9 -> 5691220000 | F9: 8 | G9: =B10-B9 -> 1 | H9: =E9*F9%/365*G9 -> 1247390.7
A10: =+A9+1 -> 3 | B10: 05.12.2017 | C10: 0 | D10: 600000000 | E10: =E9-C10+D10 -> 6291220000 | F10: 8 | G10: =B11-B10 -> 1 | H10: =E10*F10%/365*G10 -> 1378897.5
A11: =+A10+1 -> 4 | B11: 06.12.2017 | C11: 3000000000 | D11: 0 | E11: =E10-C11+D11 -> 3291220000 | F11: 8 | G11: =B12-B11 -> 0 | H11: =E11*F11%/365*G11 -> 0
A12: =+A11+1 -> 5 | B12: 06.12.2017 | C12: 500000000 | D12: 0 | E12: =E11-C12+D12 -> 2791220000 | F12: 8 | G12: =B13-B12 -> 1 | H12: =E12*F12%/365*G12 -> 611774.25
A13: =+A12+1 -> 6 | B13: 07.12.2017 | C13: 1500000000 | D13: 0 | E13: =E12-C13+D13 -> 1291220000 | F13: 8 | G13: =B14-B13 -> 4 | H13: =E13*F13%/365*G13 -> 1132028.5
A14: =+A13+1 -> 7 | B14: 11.12.2017 | C14: 0 | D14: 500000000 | E14: =E13-C14+D14 -> 1791220000 | F14: 8 | G14: =B15-B14 -> 1 | H14: =E14*F14%/365*G14 -> 392596.16
A15: =+A14+1 -> 8 | B15: 12.12.2017 | C15: 0 | D15: 100000000 | E15: =E14-C15+D15 -> 1891220000 | F15: 8 | G15: =B16-B15 -> 1 | H15: =E15*F15%/365*G15 -> 414513.97
A16: =+A15+1 -> 9 | B16: 13.12.2017 | C16: 0 | D16: 400000000 | E16: =E15-C16+D16 -> 2291220000 | F16: 8 | G16: =B17-B16 -> 1 | H16: =E16*F16%/365*G16 -> 502185.21
A17: =+A16+1 -> 10 | B17: 14.12.2017 | C17: 0 | D17: 300000000 | E17: =E16-C17+D17 -> 2591220000 | F17: 8 | G17: =B18-B17 -> 1 | H17: =E17*F17%/365*G17 -> 567938.63
A18: =+A17+1 -> 11 | B18: 15.12.2017 | C18: 0 | D18: 900000000 | E18: =E17-C18+D18 -> 3491220000 | F18: 8 | G18: =B19-B18 -> 2 | H18: =E18*F18%/365*G18 -> 1530397.8
A19: =+A18+1 -> 12 | B19: 17.12.2017 | C19: 0 | D19: 700000000 | E19: =E18-C19+D19 -> 4191220000 | F19: 8 | G19: =B20-B19 -> 1 | H19: =E19*F19%/365*G19 -> 918623.56
A20: =+A19+1 -> 13 | B20: 18.12.2017 | C20: 0 | D20: 200000000 | E20: =E19-C20+D20 -> 4391220000 | F20: 8 | G20: =B21-B20 -> 1 | H20: =E20*F20%/365*G20 -> 962459.18
... A96: =+A95+1 -> 89 | B96: 30.03.2018 | C96: 0 | D96: 200000000 | E96: =E95-C96+D96 -> 5879520000 | F96: 8 | G96: =B97-B96 -> 1 | H96: =E96*F96%/365*G96 -> 1288661.9
A97: =+A96+1 -> 90 | B97: 31.03.2018 | C97: 0 | D97: 300000000 | E97: =E96-C97+D97 -> 6179520000 | F97: 8 | G97: 1 | H97: =E97*F97%/365*G97 -> 1354415.3
A98: =+A60+1 -> 54 | H98: =E98*F98%/365*G98 -> 0
A99: ЖАМИ Бош банкдан олинган 8 фоиз ресурс маблаги | H99: =SUM(H8:H97) -> 1.2804255e+08 | I99: 1.2804255e+08 | J99: =I99-H99 -> 0.00068488717
B102: =+'2.Мол.ёр.16102-1'!B38 -> АТ "Халқ банк"нинг Ички аудит
B103: =+'2.Мол.ёр.16102-1'!B39 -> департаменти бўлим бошлиғи: | F103: =+'2.Мол.ёр.16102-1'!F39 -> А.Ҳазратқулов
B105: =+'2.Мол.ёр.16102-1'!B41 -> АТ "Халқ банк" Фаргона вилояти
B106: =+'2.Мол.ёр.16102-1'!B42 -> Бешариқ филиали бошқарувчиси: | F106: =+'2.Мол.ёр.16102-1'!F42 -> _____________
B108: =+'2.Мол.ёр.16102-1'!B44 -> Бош бухгалтери: | F108: =+'2.Мол.ёр.16102-1'!F44 -> _____________

Sheet 22203
L1: 2.1-жадвал
A2: "Агробанк" ОАТБ нинг вилоят бошқармаси Ҳудудий филиали томонидан олинган молиявий ёрдам маблаги ва унга ҳисобланган фоизларнинг тўланиши бўйича 2013 йил 1 июн холатига
B3: МАЪЛУМОТ
L4: сўмда
A5: Т/р | B5: Банк филиалининг номи | C5: Молиявий ёрдам олинган сана | D5: Сумма | E5: Фоиз ставка | F5: Бир кунлик фоиз суммаси | G5: Фоиз хисобланган кун | H5: Умумий фоиз ( сум) | I5: Филиалларга тўланди фоиз | J5: Фарқи (+;-) | K5: Молиявий ёрдам қайтарилган сана | L5: 2013 йил 1 июн холатига колдик
A9: А | B9: Б | C9: 1 | D9: =+C9+1 -> 2 | E9: =+D9+1 -> 3 | F9: =+E9+1 -> 4 | G9: =+F9+1 -> 5 | H9: =+G9+1 -> 6 | I9: =+H9+1 -> 7 | J9: 8 | K9: 9 | L9: 10
A10: Тошкент шахар Бектимир филиалига берилган ресурси
A11: 1 | B11: 12.02.15 | C11: 0 | D11: 500000000 | E11: =+D11-C11 -> 500000000 | F11: 6 | G11: =+B12-B11 -> 68 | H11: =E11*F11%/365*G11 -> 5589041.1
A12: =+A11+1 -> 2 | B12: 21.04.15 | C12: 300000000 | D12: 0 | E12: =E11-C12+D12 -> 200000000 | F12: 6 | G12: =+B13-B12 -> 64 | H12: =E12*F12%/365*G12 -> 2104109.6
A13: =+A12+1 -> 3 | B13: 24.06.15 | C13: 100000000 | D13: 0 | E13: =E12-C13+D13 -> 100000000 | F13: 6 | G13: =+B14-B13 -> 5 | H13: =E13*F13%/365*G13 -> 82191.781
A14: =+A13+1 -> 4 | B14: 29.06.15 | C14: 100000000 | D14: 0 | E14: =E13-C14+D14 -> 0 | F14: 6 | H14: =E14*F14%/365*G14 -> 0
A16: 3 | B16: Батош филиали бўйича жами: | E16: х | F16: =SUM(#REF!) -> #REF! | G16: =SUM(#REF!) -> #REF! | H16: =SUM(#REF!) -> #REF! | I16: =SUM(#REF!) -> #REF! | J16: =SUM(#REF!) -> #REF! | K16: х | L16: =SUM(#REF!) -> #REF!
A17: =+A16+#REF!+#REF!+#REF!+#REF!+#REF!+#REF! -> #REF! | B17: Жами вилоят бўйича | F17: =+F16+#REF!+#REF!+#REF!+#REF!+#REF!+#REF! -> #REF! | G17: =+G16+#REF!+#REF!+#REF!+#REF!+#REF!+#REF! -> #REF! | H17: =+H16+#REF!+#REF!+#REF!+#REF!+#REF!+#REF! -> #REF! | I17: =+I16+#REF!+#REF!+#REF!+#REF!+#REF!+#REF! -> #REF! | J17: =+J16+#REF!+#REF!+#REF!+#REF!+#REF!+#REF! -> #REF! | L17: =+L16+#REF!+#REF!+#REF! -> #REF!
C19: "Агробанк" ОАТБнинг Ички Аудит
C20: Департаменти бош мутахассиси: | I20: У.Р.Очилов
C22: Сурхондарё вилоят бошқармаси
C23: Ҳудудий филиал бошқарувчиси: | I23: А.Х.Бўронов
C25: Бош бухгалтери: | I25: У.Б.Тўрақулов

Sheet 3.Д-т фоиз
G1: 3-жадвал
A2: =""&(Шаблон!B1)&"нинг "&(Шаблон!B2)&" шахар "&(Шаблон!B3)&" филиалида мижозлар ҳисобварақлари орқали амалга оширилган дебет айланма учун улар билан тузилган Банк ҳисобварақ шартномасида белгиланган фоиз ставкасидан кам ёки ортиқча фоиз ҳисобланган ҳолатлар бўйича" -> АТ "Халқ банк"нинг Фаргона вилояти шахар Бешариқ филиали филиалида мижозлар ҳисобварақлари орқали амалга оширилган дебет айланма учун улар билан тузилган Банк ҳисобварақ шартномасида белгиланган фоиз ставкасидан кам ёки ортиқча фоиз ҳисобланган ҳолатлар бўйича
D3: М А Ъ Л У М О Т
G4: (минг сўмда)
A5: т/р | B5: Мижоз номи | C5: Фоиз ҳисобланиши | G5: Изоҳ
C6: белгиланган фоиз ставкаси | D6: ҳисобланиши керак бўлган фоиз суммаси | E6: ҳақиқатда ҳисобланган фоиз суммаси | F6: фарқи
F7: +; -
A8: А | B8: Б | C8: 1 | D8: 2 | E8: 3 | F8: 4 | G8: 5
A9: 1 | B9: Самарқанд Қудуқ Толаси фх | C9: 0.03 | D9: =(450000*3%)/1000 -> 13.5 | E9: =(450000*0.7%)/1000 -> 3.15 | F9: =+E9-D9 -> -10.35 | G9: ОКО модулига фоиз ставкаси кам киритилган
A10: =+A9+1 -> 2 | B10: Жобборов Тиркаш ктхф | C10: 0.02 | D10: =(24894367.74*C10)/1000 -> 497.88735 | E10: =(24894367.74*0.7%)/1000 -> 174.26057 | F10: =+E10-D10 -> -323.62678
A11: =+A10+1 -> 3 | B11: Мусобақа Ғолиби фх | C11: 0.01 | D11: =(10441439.13*C11)/1000 -> 104.41439 | E11: =(10441439.13*0.7%)/1000 -> 73.090074 | F11: =+E11-D11 -> -31.324317
A12: 4 | B12: Комилжон Даласи фх | C12: 0.03 | D12: =2682700*3%/1000 -> 80.481 | E12: =2682.7*0.7% -> 18.7789 | F12: =+E12-D12 -> -61.7021
A13: 5 | B13: Отабек-Феруза Савдо х\к | C13: 0.02 | D13: =48291749.69*2%/1000 -> 965.83499 | E13: =48291749.69*0.7%/1000 -> 338.04225 | F13: =+E13-D13 -> -627.79275
A14: 6 | B14: Солиха Умида фх | C14: 0.03 | D14: =2809.2*3% -> 84.276 | E14: 0 | F14: =+E14-D14 -> -84.276
A15: цуывяч | B15: жами | D15: =SUM(D9:D14) -> 1746.3937 | E15: =SUM(E9:E14) -> 607.3218 | F15: =SUM(F9:F14) -> -1139.0719
B18: =""&(Шаблон!B1)&"нинг Ички Аудит" -> АТ "Халқ банк"нинг Ички Аудит
B19: Департаменти бош мутахассиси: | F19: =Шаблон!B13 -> А.Ҳазратқулов
B21: =""&(Шаблон!B1)&" "&(Шаблон!B2)&" вилояти" -> АТ "Халқ банк" Фаргона вилояти вилояти
B22: =""&(Шаблон!B3)&" филиали бошқарувчиси:" -> Бешариқ филиали филиали бошқарувчиси: | F22: =Шаблон!B5 -> _____________
B24: Бош бухгалтери: | F24: =Шаблон!B8 -> _____________

Sheet 3а.Абонент тулов
C2: ДТ "Халқ банк"нинг Жиззах вилояти филиалида мижозлардан ойлик абонент тeловларини хисобланиши ва ундирилши буйича бўйича маълумот
A4: № | B4: БХ | C4: Уникал коди | D4: Мижоз номи | E4: жами | F4: Январ | H4: феврал | J4: март | L4: апрел | N4: май | P4: июн | R4: июл | T4: август | V4: сентябр | X4: октябр | Z4: ноябр | AB4: декабр | AD4: январ | AF4: феврал | AH4: март | AJ4: апрел | AL4: май | AN4: июн | AP4: июл | AR4: август | AT4: Ундирилмаган мабла- | AU4: Ундирилмасдан қолган маблағ | AV4: Фарки
A5: 1 | C5: 00252797 | D5: YATT ALIQULOVA ZULAYXO ABDUXALIL QIZI хисобварак а 602874818 | E5: =+SUM(F5:AR5) -> 450000 | F5: 50000 | H5: 50000 | J5: 50000 | L5: 50000 | N5: 50000 | P5: 50000 | R5: 50000 | T5: 50000 | V5: 50000 | X5: 0 | Z5: 0 | AB5: 0 | AD5: 0 | AF5: 0 | AJ5: 0 | AL5: 0 | AN5: 0 | AP5: 0 | AR5: 0 | AT5: =+AS5+AQ5+AO5+AM5+AK5+AI5+AG5+AE5+AC5+AA5+Y5+W5+U5+S5+Q5+O5+M5+K5+I5+G5 -> 0 | AU5: =+E5-AT5 -> 450000 | AV5: =+AT5-AW5 -> 0 | AW5: =SUMIF(AX:AX,C5,AY:AY) -> 0 | AX5: 04680109 | AY5: 40000
A6: =+A5+1 -> 2 | C6: 00255041 | D6: YATT ALIYEV ZAYNIDDIN OCHILOVICH 602867216 | E6: =+SUM(F6:AR6) -> 960000 | F6: 50000 | H6: 50000 | J6: 50000 | L6: 50000 | N6: 50000 | P6: 50000 | R6: 50000 | T6: 50000 | V6: 50000 | X6: 50000 | Z6: 50000 | AB6: 50000 | AD6: 150000 | AF6: 50000 | AH6: 0 | AJ6: 0 | AL6: 40000 | AN6: 40000 | AP6: 40000 | AR6: 40000 | AT6: =+AS6+AQ6+AO6+AM6+AK6+AI6+AG6+AE6+AC6+AA6+Y6+W6+U6+S6+Q6+O6+M6+K6+I6+G6 -> 0 | AU6: =+E6-AT6 -> 960000 | AV6: =+AT6-AW6 -> 0 | AW6: =SUMIF(AX:AX,C6,AY:AY) -> 0 | AX6: 04980506 | AY6: 40000
A7: =+A6+1 -> 3 | C7: 00268724 | D7: ЯТТ Окилов Олим Узганбаевич хисобланган хисобракам 463089620 | E7: =+SUM(F7:AR7) -> 1010000 | F7: 50000 | H7: 50000 | J7: 50000 | L7: 50000 | N7: 50000 | P7: 50000 | R7: 50000 | T7: 50000 | V7: 50000 | X7: 50000 | Z7: 50000 | AB7: 50000 | AD7: 150000 | AF7: 50000 | AH7: 0 | AJ7: 50000 | AL7: 40000 | AN7: 40000 | AP7: 40000 | AR7: 40000 | AT7: =+AS7+AQ7+AO7+AM7+AK7+AI7+AG7+AE7+AC7+AA7+Y7+W7+U7+S7+Q7+O7+M7+K7+I7+G7 -> 0 | AU7: =+E7-AT7 -> 1010000 | AV7: =+AT7-AW7 -> 0 | AW7: =SUMIF(AX:AX,C7,AY:AY) -> 0 | AX7: 04879712 | AY7: 40000
A8: =+A7+1 -> 4 | C8: 00294738 | D8: FORISH-NARVON MCHJ Хисобланган бошка фоизсиз даром 302781927 | E8: =+SUM(F8:AR8) -> 970000 | F8: 50000 | H8: 50000 | J8: 50000 | L8: 50000 | N8: 50000 | P8: 50000 | R8: 50000 | T8: 50000 | V8: 50000 | X8: 50000 | Z8: 50000 | AB8: 50000 | AD8: 150000 | AF8: 50000 | AH8: 0 | AJ8: 50000 | AL8: 40000 | AN8: 40000 | AP8: 40000 | AR8: 0 | AT8: =+AS8+AQ8+AO8+AM8+AK8+AI8+AG8+AE8+AC8+AA8+Y8+W8+U8+S8+Q8+O8+M8+K8+I8+G8 -> 0 | AU8: =+E8-AT8 -> 970000 | AV8: =+AT8-AW8 -> 0 | AW8: =SUMIF(AX:AX,C8,AY:AY) -> 0 | AX8: 00408323 | AY8: 40000
A9: =+A8+1 -> 5 | C9: 00298068 | D9: YATT ULASHBAYEV AMRULLO ULASHBAY O'G'LI 603045898 | E9: =+SUM(F9:AR9) -> 350000 | F9: 50000 | H9: 50000 | J9: 50000 | L9: 50000 | N9: 0 | P9: 50000 | R9: 50000 | T9: 50000 | V9: 0 | X9: 0 | Z9: 0 | AB9: 0 | AD9: 0 | AF9: 0 | AJ9: 0 | AL9: 0 | AN9: 0 | AP9: 0 | AR9: 0 | AT9: =+AS9+AQ9+AO9+AM9+AK9+AI9+AG9+AE9+AC9+AA9+Y9+W9+U9+S9+Q9+O9+M9+K9+I9+G9 -> 0 | AU9: =+E9-AT9 -> 350000 | AV9: =+AT9-AW9 -> 0 | AW9: =SUMIF(AX:AX,C9,AY:AY) -> 0 | AX9: 00599137 | AY9: 40000
A10: =+A9+1 -> 6 | C10: 00299893 | D10: YATT MANSUROVA IHBOL 603045914 | E10: =+SUM(F10:AR10) -> 400000 | F10: 50000 | H10: 50000 | J10: 50000 | L10: 50000 | N10: 50000 | P10: 50000 | R10: 50000 | T10: 50000 | V10: 0 | X10: 0 | Z10: 0 | AB10: 0 | AD10: 0 | AF10: 0 | AJ10: 0 | AL10: 0 | AN10: 0 | AP10: 0 | AR10: 0 | AT10: =+AS10+AQ10+AO10+AM10+AK10+AI10+AG10+AE10+AC10+AA10+Y10+W10+U10+S10+Q10+O10+M10+K10+I10+G10 -> 0 | AU10: =+E10-AT10 -> 400000 | AV10: =+AT10-AW10 -> 0 | AW10: =SUMIF(AX:AX,C10,AY:AY) -> 0 | AX10: 04838884 | AY10: 40000
A11: =+A10+1 -> 7 | C11: 04352777 | D11: КУШ ТЕПА БОКИЙ ХУСУСИЙ КОРХОНАСИ Хисобварак абонте 205197237 | E11: =+SUM(F11:AR11) -> 960000 | F11: 50000 | H11: 50000 | J11: 50000 | L11: 50000 | N11: 50000 | P11: 50000 | R11: 50000 | T11: 50000 | V11: 50000 | X11: 50000 | Z11: 50000 | AB11: 50000 | AD11: 150000 | AF11: 50000 | AH11: 0 | AJ11: 0 | AL11: 40000 | AN11: 40000 | AP11: 40000 | AR11: 40000 | AT11: =+AS11+AQ11+AO11+AM11+AK11+AI11+AG11+AE11+AC11+AA11+Y11+W11+U11+S11+Q11+O11+M11+K11+I11+G11 -> 0 | AU11: =+E11-AT11 -> 960000 | AV11: =+AT11-AW11 -> 0 | AW11: =SUMIF(AX:AX,C11,AY:AY) -> 0 | AX11: 04767059 | AY11: 50000
A12: =+A11+1 -> 8 | C12: 04359000 | D12: НУР ва ТИБ МЧЖ Хисобварак абонтент тулв. буй. Хис 205259063 | E12: =+SUM(F12:AR12) -> 400000 | F12: 50000 | H12: 50000 | J12: 50000 | L12: 50000 | N12: 50000 | P12: 50000 | R12: 50000 | T12: 0 | V12: 0 | X12: 0 | Z12: 0 | AB12: 0 | AD12: 0 | AE12: 50000 | AF12: 0 | AJ12: 0 | AL12: 0 | AN12: 0 | AP12: 0 | AR12: 0 | AT12: =+AS12+AQ12+AO12+AM12+AK12+AI12+AG12+AE12+AC12+AA12+Y12+W12+U12+S12+Q12+O12+M12+K12+I12+G12 -> 50000 | AU12: =+E12-AT12 -> 350000 | AV12: =+AT12-AW12 -> 50000 | AW12: =SUMIF(AX:AX,C12,AY:AY) -> 0 | AX12: 04943627 | AY12: 50000
A13: =+A12+1 -> 9 | C13: 00258107 | D13: YATT QARSHIBOEV TO'LQIN XAITBOEVICH 456500935 | E13: =+SUM(F13:AR13) -> 960000 | F13: 50000 | H13: 50000 | J13: 50000 | L13: 50000 | N13: 50000 | P13: 50000 | R13: 50000 | T13: 50000 | V13: 50000 | X13: 50000 | Z13: 50000 | AB13: 50000 | AD13: 150000 | AF13: 50000 | AH13: 0 | AJ13: 0 | AL13: 40000 | AN13: 40000 | AP13: 40000 | AR13: 40000 | AT13: =+AS13+AQ13+AO13+AM13+AK13+AI13+AG13+AE13+AC13+AA13+Y13+W13+U13+S13+Q13+O13+M13+K13+I13+G13 -> 0 | AU13: =+E13-AT13 -> 960000 | AV13: =+AT13-AW13 -> 0 | AW13: =SUMIF(AX:AX,C13,AY:AY) -> 0 | AX13: 04780246 | AY13: 50000
A14: =+A13+1 -> 10 | C14: 00290290 | D14: YATT UMAROVA DONOHON QUCHQAROVNA | E14: =+SUM(F14:AR14) -> 550000 | F14: 50000 | H14: 50000 | J14: 50000 | L14: 50000 | N14: 50000 | P14: 50000 | R14: 50000 | T14: 50000 | V14: 0 | X14: 0 | Z14: 50000 | AB14: 0 | AD14: 0 | AE14: 50000 | AF14: 0 | AG14: 50000 | AJ14: 0 | AL14: 0 | AN14: 0 | AP14: 0 | AR14: 0 | AT14: =+AS14+AQ14+AO14+AM14+AK14+AI14+AG14+AE14+AC14+AA14+Y14+W14+U14+S14+Q14+O14+M14+K14+I14+G14 -> 100000 | AU14: =+E14-AT14 -> 450000 | AV14: =+AT14-AW14 -> 100000 | AW14: =SUMIF(AX:AX,C14,AY:AY) -> 0 | AX14: 04202843 | AY14: 50000
A15: =+A14+1 -> 11 | C15: 04721465 | D15: ХУСУСИЙ ТАДБИРКОР БОСТАТОВА РУХСАТ 477793466 | E15: =+SUM(F15:AR15) -> 400000 | F15: 50000 | H15: 50000 | J15: 50000 | L15: 50000 | N15: 50000 | P15: 50000 | R15: 0 | S15: 50000 | T15: 0 | V15: 0 | X15: 0 | Z15: 50000 | AB15: 0 | AD15: 0 | AF15: 0 | AJ15: 0 | AL15: 0 | AN15: 0 | AP15: 0 | AR15: 0 | AT15: =+AS15+AQ15+AO15+AM15+AK15+AI15+AG15+AE15+AC15+AA15+Y15+W15+U15+S15+Q15+O15+M15+K15+I15+G15 -> 50000 | AU15: =+E15-AT15 -> 350000 | AV15: =+AT15-AW15 -> 50000 | AW15: =SUMIF(AX:AX,C15,AY:AY) -> 0 | AX15: 04662092 | AY15: 50000
